<?xml version='1.0'?>

<robot name="mogi_bot" xmlns:xacro="http://www.ros.org/wiki/xacro">

  <!-- Gazebo plugin -->
  <xacro:include filename="$(find versenypalya)/urdf/mogi_bot.gazebo" />
  <!-- RViz colors -->
  <xacro:include filename="$(find versenypalya)/urdf/materials.xacro" />

  <link name="base_footprint"></link>

  <joint name="base_footprint_joint" type="fixed">
    <origin xyz="0 0 0" rpy="0 0 0" />
    <parent link="base_footprint"/>
    <child link="base_link" />
  </joint>

  <!-- Robot chassis -->
  <link name='base_link'>
    <pose>0 0 0.1 0 0 0</pose>

    <inertial>
      <mass value="15.0"/>
      <origin xyz="0.0 0 0" rpy="0 0 0"/>
      <inertia
          ixx="0.1" ixy="0" ixz="0"
          iyy="0.1" iyz="0"
          izz="0.1"
      />
    </inertial>

    <collision name='collision'>
      <origin xyz="0 0 0" rpy="0 0 0"/> 
      <geometry>
        <box size=".4 .2 .1"/>
      </geometry>
    </collision>

    <visual name='base_link_visual'>
      <origin xyz="0 0 0" rpy="0 0 0"/>
      <geometry>
        <!--box size=".4 .2 .1"/-->
        <mesh filename = "package://versenypalya/meshes/mogi_bot.dae"/>
      </geometry>
      <material name="orange"/>
    </visual>

    <collision name='rear_caster_collision'>
      <origin xyz="-0.15 0 -0.05" rpy="0 0 0"/>
      <geometry>
        <sphere radius="0.0499"/>
      </geometry>
    </collision>

    <visual name='rear_caster_visual'>
      <origin xyz="-0.15 0 -0.05" rpy="0 0 0"/>
      <geometry>
        <sphere radius="0.05"/>
      </geometry>
    </visual>

    <collision name='front_caster_collision'>
      <origin xyz="0.15 0 -0.05" rpy="0 0 0"/>
      <geometry>
        <sphere radius="0.0499"/>
      </geometry>
    </collision>

    <visual name='front_caster_visual'>
      <origin xyz="0.15 0 -0.05" rpy="0 0 0"/>
      <geometry>
        <sphere radius="0.05"/>
      </geometry>
    </visual>

  </link>

  <!-- Wheels -->
  <joint type="continuous" name="left_wheel_joint">
    <origin xyz="0 0.15 0" rpy="0 0 0"/>
    <child link="left_wheel"/>
    <parent link="base_link"/>
    <axis xyz="0 1 0" rpy="0 0 0"/>
    <limit effort="10000" velocity="1000"/>
    <dynamics damping="1.0" friction="1.0"/>
  </joint>

  <link name='left_wheel'>
    <inertial>
      <mass value="5.0"/>
      <origin xyz="0 0 0" rpy="0 1.5707 1.5707"/>
      <inertia
          ixx="0.1" ixy="0" ixz="0"
          iyy="0.1" iyz="0"
          izz="0.1"
      />
    </inertial>

    <collision name='collision'>
      <origin xyz="0 0 0" rpy="0 1.5707 1.5707"/> 
      <geometry>
        <cylinder radius=".1" length=".05"/>
      </geometry>
    </collision>

    <visual name='left_wheel_visual'>
      <origin xyz="0 0 0" rpy="0 1.5707 1.5707"/>
      <geometry>
        <!--cylinder radius=".1" length=".05"/-->
        <mesh filename = "package://versenypalya/meshes/wheel.dae"/>
      </geometry>
      <material name="green"/>
    </visual>
  </link>

  <joint type="continuous" name="right_wheel_joint">
    <origin xyz="0 -0.15 0" rpy="0 0 0"/>
    <child link="right_wheel"/>
    <parent link="base_link"/>
    <axis xyz="0 1 0" rpy="0 0 0"/>
    <limit effort="10000" velocity="1000"/>
    <dynamics damping="1.0" friction="1.0"/>
  </joint>

  <link name='right_wheel'>
    <inertial>
      <mass value="5.0"/>
      <origin xyz="0 0 0" rpy="0 1.5707 1.5707"/>
      <inertia
          ixx="0.1" ixy="0" ixz="0"
          iyy="0.1" iyz="0"
          izz="0.1"
      />
    </inertial>

    <collision name='collision'>
      <origin xyz="0 0 0" rpy="0 1.5707 1.5707"/> 
      <geometry>
        <cylinder radius=".1" length=".05"/>
      </geometry>
    </collision>

    <visual name='right_wheel_visual'>
      <origin xyz="0 0 0" rpy="0 1.5707 1.5707"/>
      <geometry>
        <!--cylinder radius=".1" length=".05"/-->
        <mesh filename = "package://versenypalya/meshes/wheel.dae"/>
      </geometry>
      <material name="green"/>
    </visual>
  </link>

  <!-- Camera -->
  <joint type="fixed" name="camera_joint">
    <origin xyz="0.225 0 0.075" rpy="0 0 0"/>
    <child link="camera_link"/>
    <parent link="base_link"/>
    <axis xyz="0 1 0" />
  </joint>

  <link name='camera_link'>
    <pose>0 0 0 0 0 0</pose>
    <inertial>
      <mass value="0.1"/>
      <origin xyz="0 0 0" rpy="0 0 0"/>
      <inertia
          ixx="1e-6" ixy="0" ixz="0"
          iyy="1e-6" iyz="0"
          izz="1e-6"
      />
    </inertial>

    <collision name='collision'>
      <origin xyz="0 0 0" rpy="0 0 0"/> 
      <geometry>
        <box size=".05 .05 .05"/>
      </geometry>
    </collision>

    <visual name='camera_link_visual'>
      <origin xyz="0 0 0" rpy="0 0 0"/>
      <geometry>
        <box size=".05 .05 .05"/>
      </geometry>
    </visual>

  </link>

  <gazebo reference="camera_link">
    <material>Gazebo/Red</material>
  </gazebo>

  <joint type="fixed" name="camera_optical_joint">
    <origin xyz="0 0 0" rpy="-1.5707 0 -1.5707"/>
    <child link="camera_link_optical"/>
    <parent link="camera_link"/>
  </joint>

  <link name="camera_link_optical">
  </link>

  <!-- IMU -->
  <joint name="imu_joint" type="fixed">
    <origin xyz="0 0 0" rpy="0 0 0" />
    <parent link="base_link"/>
    <child link="imu_link" />
  </joint>

  <link name="imu_link">
  </link>

  <!-- Lidar -->
  <joint type="fixed" name="scan_joint">
    <origin xyz="0.0 0 0.15" rpy="0 0 0"/>
    <child link="scan_link"/>
    <parent link="base_link"/>
    <axis xyz="0 1 0" rpy="0 0 0"/>
  </joint>

  <link name='scan_link'>
    <inertial>
      <mass value="1e-5"/>
      <origin xyz="0 0 0" rpy="0 0 0"/>
      <inertia
          ixx="1e-6" ixy="0" ixz="0"
          iyy="1e-6" iyz="0"
          izz="1e-6"
      />
    </inertial>

    <collision name='collision'>
      <origin xyz="0 0 0" rpy="0 0 0"/> 
      <geometry>
        <box size=".1 .1 .1"/>
      </geometry>
    </collision>

    <visual name='scan_link_visual'>
      <origin xyz="0 0 0" rpy="0 0 0"/>
      <geometry>
        <mesh filename = "package://versenypalya/meshes/lidar.dae"/>
      </geometry>
    </visual>

  </link>

  <!-- Velodyne -->
  <!--joint type="fixed" name="velodyne_joint">
    <origin xyz="0.0 0 0.10" rpy="0 0 0"/>
    <child link="velodyne_link"/>
    <parent link="base_link"/>
    <axis xyz="0 1 0" rpy="0 0 0"/>
  </joint>

  <link name='velodyne_link'>
    <inertial>
      <mass value="1e-5"/>
      <origin xyz="0 0 0" rpy="0 0 0"/>
      <inertia
          ixx="1e-6" ixy="0" ixz="0"
          iyy="1e-6" iyz="0"
          izz="1e-6"
      />
    </inertial>

    <collision name='collision'>
      <origin xyz="0 0 0" rpy="0 0 0"/> 
      <geometry>
        <box size=".1 .1 .1"/>
      </geometry>
    </collision>

    <visual name='velodyne_link_visual'>
      <origin xyz="0 0 0" rpy="0 0 0"/>
      <geometry>
        <mesh filename = "package://versenypalya/meshes/vlp16.dae"/>
      </geometry>
    </visual>

  </link-->

</robot>